Workbook

Sheet График ТКРС
A1: Участок | B1: Бригада | C1: Наличие НЗ/ПР | D1: статус | E1: Скв | F1: Куст | G1: дата начала (план) | H1: дата ГТМ | I1: заверш рем (план) | J1: Дн. + актировка с 01.12-15.03 (формула) | K1: Метео | L1: Продолжительность | M1: Qж/Qг, м3/сут | N1: Н2О, % | O1: Qн, тн/сут | P1: ГФ, м3/м3 | Q1: вид КР | R1: Планируемый объем работ | S1: Дата выхода их бурения | T1: начГРП | U1: стадий ГРП | V1: заверш ГРП | W1: Приоритет
A2: 2 | B2: 1 КРС ООО "ИНК-ТКРС" | C2: готов | D2: выполняется | E2: Vt_5705 | F2: 57 | G2: 46131 | I2: 46138 | J2: 7 | K2: 0 | L2: 168 | M2: 49 | N2: 2 | O2: 0 | P2: 399 | Q2: КР10-1 | R2: смена НКТ 114х89 | S2: - | W2: нет в перечне
A3: 1 | B3: 1 КРС ООО "ИНК-ТКРС" | E3: Vt_б/н | G3: 46138 | I3: 46146 | J3: 8 | K3: 0 | L3: 192 | M3: 0 | N3: 0 | O3: 0 | Q3: ТР5-1 | R3: Смена ЭЦН на отказной скважине | S3: - | W3: нет в перечне
A4: 1 | B4: 1 КРС ООО "ИНК-ТКРС" | E4: Vt_б/н | G4: 46146 | I4: 46154 | J4: 8 | K4: 0 | L4: 192 | M4: 0 | N4: 0 | O4: 0 | Q4: ТР5-1 | R4: Смена ЭЦН на отказной скважине | S4: - | W4: нет в перечне
A5: 2 | B5: 1 КРС ООО "ИНК-ТКРС" | C5: нз нет | D5: гнкт | E5: Vt_5010 | F5: 50 | G5: 46154 | I5: 46162 | J5: 8 | K5: 0 | L5: 192 | M5: 298 | N5: 10 | O5: 218 | P5: 400 | Q5: КР-ОС-6 | R5: Спуск ЭЦН после ЗОС | S5: 19.02.2026 | T5: 46102 | U5: 1 | V5: 46103 | W5: Высокий
A6: 2 | B6: 1 КРС ООО "ИНК-ТКРС" | D6: ож гнкт ож зос | E6: Vt_5009 | F6: 50 | G6: 46162 | I6: 46172 | J6: 10 | K6: 0 | L6: 240 | M6: 251 | N6: 10 | O6: 183 | P6: 400 | Q6: КР-ОС-6 | R6: Спуск ЭЦН после ЗОС/КГРП | S6: 11.12.2025 | T6: 46108 | U6: 1 | V6: 46111 | W6: Высокий
A7: 1 | B7: 1 КРС ООО "ИНК-ТКРС" | E7: Ya_838 | F7: 214 | G7: 46172 | I7: 46182 | J7: 10 | K7: 0 | L7: 240 | M7: 100 | N7: 0 | O7: 0 | P7: 199 | Q7: КР7-2 | R7: ПР к ГРП | S7: - | T7: 46247 | U7: 1 | V7: 46251 | W7: нет в перечне
A8: 1 | B8: 1 КРС ООО "ИНК-ТКРС" | E8: Ya_812 | F8: 219 | G8: 46182 | I8: 46192 | J8: 10 | K8: 0 | L8: 240 | M8: 0 | N8: 0 | O8: 0 | P8: 0 | Q8: ТР6-1 | R8: Прочие ГТМ ППД ГАЗ | S8: - | W8: КРС
A9: 1 | B9: 1 КРС ООО "ИНК-ТКРС" | E9: Ya_888 | F9: 222 | G9: 46192 | I9: 46200 | J9: 8 | K9: 0 | L9: 192 | M9: 100000 | N9: 0 | O9: 39 | P9: 0 | Q9: ТР6-1 | R9: Прочие ГТМ ППД ГАЗ | S9: - | W9: ЗОС
A10: 1 | B10: 1 КРС ООО "ИНК-ТКРС" | E10: Ya_844 | F10: 216 | G10: 46200 | I10: 46208 | J10: 8 | K10: 0 | L10: 192 | M10: 0 | N10: 0 | O10: 0 | P10: 0 | Q10: ТР6-1 | R10: смена нкт (ППР) | S10: - | W10: КРС ЗОС
A11: 1 | B11: 1 КРС ООО "ИНК-ТКРС" | E11: Ya_820 | F11: 233 | G11: 46208 | I11: 46222 | J11: 14 | K11: 0 | L11: 336 | M11: 0 | N11: 0 | O11: 0 | P11: 0 | Q11: ТР6-1 | R11: смена нкт (ППР) | S11: - | W11: КРС ЗОС
A12: 1 | B12: 1 КРС ООО "ИНК-ТКРС" | E12: Ya_б/н | G12: 46222 | I12: 46230 | J12: 8 | K12: 0 | L12: 192 | M12: 0 | N12: 0 | O12: 0 | Q12: ТР5-1 | R12: Смена ЭЦН на отказной скважине | S12: - | W12: нет в перечне
A13: 2 | B13: 2 КРС ООО "ИНК-ТКРС" | C13: готов | D13: выполняется | E13: Vt_8403 | F13: 84 | G13: 46106 | I13: 46172 | J13: 66 | K13: 0 | L13: 1584 | M13: 59 | N13: 22 | O13: 37 | P13: 70 | Q13: КР3-1.1 | R13: Прихват ЭЦН в колонне, отстрел НКТ | S13: 20.02.2025 | W13: Средний
A14: 2 | B14: 2 КРС ООО "ИНК-ТКРС" | D14: ож эцн | E14: Ic_375 | F14: 9 | G14: 46172 | I14: 46202 | J14: 30 | K14: 0 | L14: 720 | M14: 86 | N14: 54 | O14: 32 | P14: 155 | Q14: КР3-1.1 | R14: ЛА при смене | S14: - | W14: Средний
A15: 2 | B15: 3 КРС ООО "ИНК-ТКРС" | C15: готов | D15: выполняется | E15: Vt_9430 | F15: 94 | G15: 46133 | I15: 46136 | J15: 3 | K15: 0 | L15: 72 | M15: 0 | N15: 0 | O15: 0 | Q15: КР-ОС-8 | R15: извлечение ЭЦН спуск воронки Н=1710м (подъем Э-200-2400) | S15: - | W15: нет в перечне
A16: 2 | B16: 3 КРС ООО "ИНК-ТКРС" | C16: готов | E16: Vt_094г | F16: 94 | G16: 46136 | I16: 46137 | J16: 1 | K16: 0 | L16: 24 | M16: 320 | N16: 0 | O16: 0 | Q16: ТР8-1 | R16: извлечение для ревизии с автокрана | S16: - | W16: нет в перечне
A17: 2 | B17: 3 КРС ООО "ИНК-ТКРС" | E17: Vt_б/н | G17: 46137 | I17: 46145 | J17: 8 | K17: 0 | L17: 192 | M17: 0 | N17: 0 | O17: 0 | Q17: ТР5-1 | R17: Смена ЭЦН на отказной скважине | S17: - | W17: нет в перечне
A18: 2 | B18: 3 КРС ООО "ИНК-ТКРС" | C18: пр нет | D18: ож эцн | E18: Vt_094г | F18: 94 | G18: 46145 | I18: 46146 | J18: 1 | K18: 0 | L18: 24 | M18: 320 | N18: 0 | O18: 0 | Q18: ТР8-1 | R18: Спуск ЭЦН автокрана | S18: - | W18: нет в перечне
A19: 2 | B19: 4 КРС ООО "ИНК-ТКРС" | C19: готов | D19: выполняется | E19: Vt_3406 | F19: 34 | G19: 46097 | I19: 46143 | J19: 46 | K19: 0 | L19: 1104 | M19: 1167 | N19: 88 | O19: 113 | P19: 219 | Q19: КР3-1.1 | R19: ЛА, НЗ (разбуривание МГРП), Смена ЭЦН на отказной скважине, Увеличение ремонта за счет доп работ. ПВР | S19: - | W19: -
A20: 2 | B20: 4 КРС ООО "ИНК-ТКРС" | D20: ож подгот ож эцн | E20: Vt_3401 | F20: 34 | G20: 46143 | I20: 46151 | J20: 8 | K20: 0 | L20: 192 | M20: 100 | N20: 60 | O20: 32 | P20: 350 | Q20: ТР5-1 | R20: смена ЭЦН на отказной скважине | S20: - | W20: за рамками трех месяцев
A21: 2 | B21: 4 КРС ООО "ИНК-ТКРС" | D21: ож подгот | E21: Vt_3403 | F21: 34 | G21: 46151 | I21: 46159 | J21: 8 | K21: 0 | L21: 192 | M21: 74 | N21: 72 | O21: 17 | P21: 282 | Q21: ТР5-1 | R21: Смена ЭЦН на отказной скважине | S21: - | W21: Низкий
A22: 2 | B22: 4 КРС ООО "ИНК-ТКРС" | E22: Vt_б/н | G22: 46159 | I22: 46167 | J22: 8 | K22: 0 | L22: 192 | M22: 0 | N22: 0 | O22: 0 | Q22: ТР5-1 | R22: Смена ЭЦН на отказной скважине | S22: - | W22: нет в перечне
A23: 2 | B23: 4 КРС ООО "ИНК-ТКРС" | E23: Vt_б/н | G23: 46167 | I23: 46175 | J23: 8 | K23: 0 | L23: 192 | M23: 0 | N23: 0 | O23: 0 | Q23: ТР5-1 | R23: Смена ЭЦН на отказной скважине | S23: - | W23: нет в перечне
A24: 2 | B24: 4 КРС ООО "ИНК-ТКРС" | E24: Vt_8410 | F24: 84 | G24: 46175 | I24: 46185 | J24: 10 | K24: 0 | L24: 240 | M24: 600 | N24: 0 | O24: 0 | P24: 0 | Q24: КР9-1 | R24: Перевод в ППД. | S24: 25.08.2025 | W24: Высокий
A25: 2 | B25: 4 КРС ООО "ИНК-ТКРС" | E25: Vt_8409 | F25: 84 | G25: 46185 | I25: 46195 | J25: 10 | K25: 0 | L25: 240 | M25: 500 | N25: 0 | O25: 0 | P25: 683 | Q25: КР9-1 | R25: Подъем ЭЦН, спуск пакера ППД. | S25: 26.07.2025 | W25: -
A26: 2 | B26: 4 КРС ООО "ИНК-ТКРС" | E26: Vt_8412 | F26: 84 | G26: 46195 | I26: 46203 | J26: 8 | K26: 0 | L26: 192 | M26: 243 | N26: 60 | O26: 79 | P26: 330 | Q26: КР-ОС-1 | R26: Спуск ЭЦН после КГРП и отработки ЗОС | S26: 02.02.2026 | W26: -
A27: 2 | B27: 5 КРС ООО "ИНК-ТКРС" | C27: готов | D27: выполняется | E27: Ic_350 | F27: 7 | G27: 46131 | I27: 46135 | J27: 4 | K27: 0 | L27: 96 | M27: 77 | N27: 90 | O27: 6 | P27: 374 | Q27: ТР5-1 | R27: спуск эцн над головой аварийного оборудования | S27: - | W27: нет в перечне
A28: 2 | B28: 5 КРС ООО "ИНК-ТКРС" | C28: готов | E28: Ic_401 | F28: 7 | G28: 46135 | I28: 46149 | J28: 14 | K28: 0 | L28: 336 | M28: 106 | N28: 66 | O28: 30 | P28: 239 | Q28: КР13-1.1 | R28: КОПС извлечение аварийного скребка каскад | S28: - | W28: Средний
A29: 2 | B29: 5 КРС ООО "ИНК-ТКРС" | E29: Ic_919 | F29: 9 | G29: 46149 | I29: 46174 | J29: 25 | K29: 0 | L29: 600 | M29: 20 | N29: 1 | O29: 16 | P29: 390 | Q29: КР13-1.1 | R29: ВЦ по ЗТР, смена ЭЦН | S29: - | W29: Низкий
A30: 1 | B30: 5 КРС ООО "ИНК-ТКРС" | E30: Vt_б/н | G30: 46174 | I30: 46182 | J30: 8 | K30: 0 | L30: 192 | M30: 0 | N30: 0 | O30: 0 | Q30: ТР5-1 | R30: смена ЭЦН на отказной скважине с доп работами | S30: - | W30: нет в перечне
A31: 2 | B31: 5 КРС ООО "ИНК-ТКРС" | D31: ож гнкт | E31: Vt_4605 | F31: 46 | G31: 46182 | I31: 46196 | J31: 14 | K31: 0 | L31: 336 | M31: 300 | N31: 0 | O31: 0 | P31: 0 | Q31: КР7-2 | R31: ПР к ГРП по результам ГНКТ | S31: 17.12.2024 | T31: 46194 | U31: 1 | V31: 46196 | W31: Высокий
A32: 2 | B32: 5 КРС ООО "ИНК-ТКРС" | E32: Vt_4603 | F32: 46 | G32: 46196 | I32: 46206 | J32: 10 | K32: 0 | L32: 240 | M32: 800 | N32: 0 | O32: 0 | P32: 0 | Q32: КР9-1 | R32: Перевод в ППД | S32: 17.10.2024 | W32: Низкий
A33: 1 | B33: 5 КРС ООО "ИНК-ТКРС" | D33: ож гнкт | E33: Vt_4406 | F33: 44 | G33: 46206 | I33: 46214 | J33: 8 | K33: 0 | L33: 192 | M33: 33 | N33: 49 | O33: 14 | P33: 441 | Q33: ТР5-1 | R33: Смена ЭЦН на отказной скважине | S33: 17.06.2024 | W33: Средний
A34: 1 | B34: 6 КРС ООО "ИНК-ТКРС" | D34: выполняется | E34: Vt_4604 | F34: 46 | G34: 46133 | I34: 46139 | J34: 6 | K34: 0 | L34: 144 | M34: 423 | N34: 68 | O34: 110 | P34: 240 | Q34: ТР5-1 | R34: смена ЭЦН на отказной скважине по рез-ту КЗИ возможно ПДМ до сростка | S34: 18.11.2024 | W34: -
A35: 1 | B35: 6 КРС ООО "ИНК-ТКРС" | E35: Vt_б/н | G35: 46139 | I35: 46147 | J35: 8 | K35: 0 | L35: 192 | M35: 0 | N35: 0 | O35: 0 | Q35: ТР5-1 | R35: смена ЭЦН на отказной скважине с доп работами | S35: - | W35: нет в перечне
A36: 1 | B36: 6 КРС ООО "ИНК-ТКРС" | E36: Vt_б/н | G36: 46147 | I36: 46155 | J36: 8 | K36: 0 | L36: 192 | M36: 0 | N36: 0 | O36: 0 | Q36: ТР5-1 | R36: смена ЭЦН на отказной скважине с доп работами | S36: - | W36: нет в перечне
A37: 1 | B37: 6 КРС ООО "ИНК-ТКРС" | D37: эцн в налич | E37: Da_537 | F37: 15 | G37: 46155 | I37: 46161 | J37: 6 | K37: 0 | L37: 144 | M37: 74 | N37: 59 | O37: 25 | P37: 129 | Q37: ТР5-1 | R37: Смена ЭЦН на отказной скважине | S37: - | W37: высокий
A38: 1 | B38: 6 КРС ООО "ИНК-ТКРС" | D38: эцн в налич | E38: Da_515 | F38: 10 | G38: 46161 | I38: 46167 | J38: 6 | K38: 0 | L38: 144 | M38: 181 | N38: 92 | O38: 12 | P38: 32 | Q38: ТР5-1 | R38: Смена ЭЦН на отказной скважине | S38: - | W38: нет в перечне
A39: 1 | B39: 6 КРС ООО "ИНК-ТКРС" | D39: эцн в налич | E39: Da_543 | F39: 17 | G39: 46167 | I39: 46176 | J39: 8 | K39: 1 | L39: 216 | M39: 320 | N39: 65 | O39: 94 | P39: 220 | Q39: КР7-1 | R39: смена ЭЦН на МТР работает Э-700 | S39: - | W39: высокий
A40: 1 | B40: 6 КРС ООО "ИНК-ТКРС" | E40: Da_517 | F40: 19 | G40: 46176 | I40: 46184 | J40: 7 | K40: 1 | L40: 192 | M40: 12 | N40: 0 | O40: 10 | P40: 254 | Q40: КР13-1.1 | R40: КОПС | S40: - | W40: нет в перечне
...

Sheet Недельный график ТКРС
A1: ЦДНГ | B1: Бригада | C1: Скв | D1: Куст | E1: дата начала (план) | F1: заверш рем (план) | G1: Продолжительность | H1: Qж/Qг, м3/сут | I1: Н2О, % | J1: Qн, тн/сут | K1: вид КР | L1: Планируемый объем работ | M1: Дата выхода их бурения | N1: начГРП | O1: стадий ГРП | P1: заверш ГРП
A2: запад | B2: 33 КРС ООО "ИНК-ТКРС" | C2: Vt_8811 | D2: 88 | E2: 46080 | F2: 46090 | G2: 240 | H2: 287 | I2: 35 | J2: 151 | K2: КР-ОС-6 | L2: отработка , спуск ЭЦН. | M2: 10.02.2026 | S2: =_xlfn.XLOOKUP(Недельный_график_ТКРС[[#This Row],[Скв]],'Каталог мероприятий'!A:A,'Каталог мероприятий'!N:N,"нет карточки") -> ООО "ИНК-ТКРС" | T2: =_xlfn.XLOOKUP(Недельный_график_ТКРС[[#This Row],[Скв]],'Каталог мероприятий'!A:A,'Каталог мероприятий'!O:O,"нет карточки") -> Бригада КГРП | U2: =_xlfn.XLOOKUP(Недельный_график_ТКРС[[#This Row],[Скв]],'Каталог мероприятий'!A:A,'Каталог мероприятий'!Q:Q) -> КР-ОС-8
A3: запад | B3: 31 КРС ООО "ИНК-ТКРС" | C3: Btw_1608рс | D3: 16 | E3: 46074 | F3: 46094 | G3: 480 | H3: 240 | I3: 0 | J3: 0 | K3: КР13-13 | L3: Разбуривание портов, с полным поглощением, после ГРП. ГИС под закачкой на ГНКТ (ОПП). | M3: - | S3: =_xlfn.XLOOKUP(Недельный_график_ТКРС[[#This Row],[Скв]],'Каталог мероприятий'!A:A,'Каталог мероприятий'!N:N,"нет карточки") -> нет карточки | T3: =_xlfn.XLOOKUP(Недельный_график_ТКРС[[#This Row],[Скв]],'Каталог мероприятий'!A:A,'Каталог мероприятий'!O:O,"нет карточки") -> нет карточки | U3: =_xlfn.XLOOKUP(Недельный_график_ТКРС[[#This Row],[Скв]],'Каталог мероприятий'!A:A,'Каталог мероприятий'!Q:Q) -> #N/A
A4: запад | B4: Бригада КГРП ООО "ИНК-ТКРС" | C4: Vt_8809 | D4: 88 | E4: 46083 | F4: 46089 | G4: 144 | H4: 180 | I4: 70 | J4: 44 | K4: КР7-1 | L4: ОПЗ водой 300 м3 | M4: - | S4: =_xlfn.XLOOKUP(Недельный_график_ТКРС[[#This Row],[Скв]],'Каталог мероприятий'!A:A,'Каталог мероприятий'!N:N,"нет карточки") -> нет карточки | T4: =_xlfn.XLOOKUP(Недельный_график_ТКРС[[#This Row],[Скв]],'Каталог мероприятий'!A:A,'Каталог мероприятий'!O:O,"нет карточки") -> нет карточки | U4: =_xlfn.XLOOKUP(Недельный_график_ТКРС[[#This Row],[Скв]],'Каталог мероприятий'!A:A,'Каталог мероприятий'!Q:Q) -> #N/A
A5: запад | B5: Звено ОС №3 ООО "ИНК-ТКРС" | C5: Bt_1505 | D5: 15 | E5: 46083 | F5: 46093 | G5: 240 | H5: 221 | I5: 1 | J5: 177 | K5: КР-ОС-6 | L5: отработка после ГРП | M5: - | N5: 46065 | O5: 4 | P5: 46074 | S5: =_xlfn.XLOOKUP(Недельный_график_ТКРС[[#This Row],[Скв]],'Каталог мероприятий'!A:A,'Каталог мероприятий'!N:N,"нет карточки") -> нет карточки | T5: =_xlfn.XLOOKUP(Недельный_график_ТКРС[[#This Row],[Скв]],'Каталог мероприятий'!A:A,'Каталог мероприятий'!O:O,"нет карточки") -> нет карточки | U5: =_xlfn.XLOOKUP(Недельный_график_ТКРС[[#This Row],[Скв]],'Каталог мероприятий'!A:A,'Каталог мероприятий'!Q:Q) -> #N/A
A6: запад | B6: 15 ГНКТ ООО "ИНК-ТКРС" | C6: Vt_8709 | D6: 87 | E6: 46083 | F6: 46086 | G6: 72 | H6: 383 | I6: 45 | J6: 173 | K6: КР13-1.3НТ | L6: ВЦ НКТ | M6: - | S6: =_xlfn.XLOOKUP(Недельный_график_ТКРС[[#This Row],[Скв]],'Каталог мероприятий'!A:A,'Каталог мероприятий'!N:N,"нет карточки") -> ООО "ИНК-ТКРС" | T6: =_xlfn.XLOOKUP(Недельный_график_ТКРС[[#This Row],[Скв]],'Каталог мероприятий'!A:A,'Каталог мероприятий'!O:O,"нет карточки") -> 5 | U6: =_xlfn.XLOOKUP(Недельный_график_ТКРС[[#This Row],[Скв]],'Каталог мероприятий'!A:A,'Каталог мероприятий'!Q:Q) -> ТР13-2
A7: запад | B7: 13 КРС ООО "ИНК-ТКРС" | C7: Vt_5109 | D7: 51 | E7: 46080 | F7: 46110 | G7: 720 | H7: 321 | I7: 46 | J7: 185 | K7: КР3-1 | L7: ЛА, (Отвернули НКТ. Произвели извлечение запыжованного кабеля) Разбуривание МГРП, ПВР и ОПЗ. | M7: - | S7: =_xlfn.XLOOKUP(Недельный_график_ТКРС[[#This Row],[Скв]],'Каталог мероприятий'!A:A,'Каталог мероприятий'!N:N,"нет карточки") -> ООО "ИНК-ТКРС" | T7: =_xlfn.XLOOKUP(Недельный_график_ТКРС[[#This Row],[Скв]],'Каталог мероприятий'!A:A,'Каталог мероприятий'!O:O,"нет карточки") -> 13 | U7: =_xlfn.XLOOKUP(Недельный_график_ТКРС[[#This Row],[Скв]],'Каталог мероприятий'!A:A,'Каталог мероприятий'!Q:Q) -> КР13-2
A8: запад | B8: 6 КРС ООО "ИНК-ТКРС" | C8: Bt_1501 | D8: 15 | E8: 46080 | F8: 46094 | G8: 336 | H8: 405 | I8: 0 | J8: 331 | K8: КР13-2 | L8: Подъем воронки, разбуривание МГРП, НЗ и ОПЗ, спуск ЭЦН. | M8: - | S8: =_xlfn.XLOOKUP(Недельный_график_ТКРС[[#This Row],[Скв]],'Каталог мероприятий'!A:A,'Каталог мероприятий'!N:N,"нет карточки") -> ООО "ИНК-ТКРС" | T8: =_xlfn.XLOOKUP(Недельный_график_ТКРС[[#This Row],[Скв]],'Каталог мероприятий'!A:A,'Каталог мероприятий'!O:O,"нет карточки") -> 5 | U8: =_xlfn.XLOOKUP(Недельный_график_ТКРС[[#This Row],[Скв]],'Каталог мероприятий'!A:A,'Каталог мероприятий'!Q:Q) -> ТР14-1.2
A9: запад | B9: 6 КРС ООО "ИНК-ТКРС" | C9: Vt_089г | D9: 89 | E9: 46076 | F9: 46080 | G9: 96 | H9: 200 | I9: 0 | J9: 0 | K9: ТР8-1 | L9: Спуск ЭЦН с автокрана | M9: - | S9: =_xlfn.XLOOKUP(Недельный_график_ТКРС[[#This Row],[Скв]],'Каталог мероприятий'!A:A,'Каталог мероприятий'!N:N,"нет карточки") -> ООО "ИНК-ТКРС" | T9: =_xlfn.XLOOKUP(Недельный_график_ТКРС[[#This Row],[Скв]],'Каталог мероприятий'!A:A,'Каталог мероприятий'!O:O,"нет карточки") -> 0 | U9: =_xlfn.XLOOKUP(Недельный_график_ТКРС[[#This Row],[Скв]],'Каталог мероприятий'!A:A,'Каталог мероприятий'!Q:Q) -> ТР8-1
A10: север | B10: 27 КРС ООО "ИНК-ТКРС" | C10: Mr_1506 | D10: 15 | E10: 46074 | F10: 46095 | G10: 504 | H10: 1000 | I10: 0 | J10: 0 | K10: КР10-1 | L10: Подъем пакера ППД, открываем все порты. Спуск 2-х ПО, ОП всех портов и заколонного пакера на гл.3409м. По результатам ОП предусмотреть, открытие портов и ОПЗ по 10м3 12% HCl на порт. Спуск пакера ППД. | M10: - | S10: =_xlfn.XLOOKUP(Недельный_график_ТКРС[[#This Row],[Скв]],'Каталог мероприятий'!A:A,'Каталог мероприятий'!N:N,"нет карточки") -> ООО "ИНК-ТКРС" | T10: =_xlfn.XLOOKUP(Недельный_график_ТКРС[[#This Row],[Скв]],'Каталог мероприятий'!A:A,'Каталог мероприятий'!O:O,"нет карточки") -> 0 | U10: =_xlfn.XLOOKUP(Недельный_график_ТКРС[[#This Row],[Скв]],'Каталог мероприятий'!A:A,'Каталог мероприятий'!Q:Q) -> КР10-1
A11: центр | B11: 6 Андижон ООО "АндижонНГКТваБ"-Русь" | C11: Au_011вз | D11: 2 | E11: 46083 | F11: 46087 | G11: 96 | H11: 0 | I11: 0 | J11: 0 | K11: ТР11-1 | L11: Извлечение ЭЦН | M11: - | S11: =_xlfn.XLOOKUP(Недельный_график_ТКРС[[#This Row],[Скв]],'Каталог мероприятий'!A:A,'Каталог мероприятий'!N:N,"нет карточки") -> нет карточки | T11: =_xlfn.XLOOKUP(Недельный_график_ТКРС[[#This Row],[Скв]],'Каталог мероприятий'!A:A,'Каталог мероприятий'!O:O,"нет карточки") -> нет карточки | U11: =_xlfn.XLOOKUP(Недельный_график_ТКРС[[#This Row],[Скв]],'Каталог мероприятий'!A:A,'Каталог мероприятий'!Q:Q) -> #N/A
A12: центр | B12: 7 Андижон ООО "АндижонНГКТваБ"-Русь" | C12: Au_447 | D12: 91 | E12: 46082 | F12: 46091 | G12: 216 | H12: 14 | I12: 1 | J12: 12 | K12: ТР5-1 | L12: Смена ЭЦН на отказной скважине | M12: - | S12: =_xlfn.XLOOKUP(Недельный_график_ТКРС[[#This Row],[Скв]],'Каталог мероприятий'!A:A,'Каталог мероприятий'!N:N,"нет карточки") -> ООО "Андижон" | T12: =_xlfn.XLOOKUP(Недельный_график_ТКРС[[#This Row],[Скв]],'Каталог мероприятий'!A:A,'Каталог мероприятий'!O:O,"нет карточки") -> 5 | U12: =_xlfn.XLOOKUP(Недельный_график_ТКРС[[#This Row],[Скв]],'Каталог мероприятий'!A:A,'Каталог мероприятий'!Q:Q) -> ТР13-2
A13: центр | B13: 2 Андижон ООО "АндижонНГКТваБ"-Русь" | C13: Ya_180 | D13: 18 | E13: 46081 | F13: 46088 | G13: 168 | H13: 280 | I13: 93 | J13: 16 | K13: КР7-1 | L13: НЗ ОПЗ на отказной скважине | M13: - | S13: =_xlfn.XLOOKUP(Недельный_график_ТКРС[[#This Row],[Скв]],'Каталог мероприятий'!A:A,'Каталог мероприятий'!N:N,"нет карточки") -> ООО "Андижон" | T13: =_xlfn.XLOOKUP(Недельный_график_ТКРС[[#This Row],[Скв]],'Каталог мероприятий'!A:A,'Каталог мероприятий'!O:O,"нет карточки") -> 0 | U13: =_xlfn.XLOOKUP(Недельный_график_ТКРС[[#This Row],[Скв]],'Каталог мероприятий'!A:A,'Каталог мероприятий'!Q:Q) -> КР7-1
A14: центр | B14: Звено ОС №1 ООО "ИНК-ТКРС" | C14: Ki_4501 | D14: 45 | E14: 46076 | F14: 46090 | G14: 336 | H14: 548 | I14: 90 | J14: 46 | K14: КР-ОС-6 | L14: отработка ЭЦНом 7 суток | M14: Пробурена | S14: =_xlfn.XLOOKUP(Недельный_график_ТКРС[[#This Row],[Скв]],'Каталог мероприятий'!A:A,'Каталог мероприятий'!N:N,"нет карточки") -> ООО "ИНК-ТКРС" | T14: =_xlfn.XLOOKUP(Недельный_график_ТКРС[[#This Row],[Скв]],'Каталог мероприятий'!A:A,'Каталог мероприятий'!O:O,"нет карточки") -> 18 | U14: =_xlfn.XLOOKUP(Недельный_график_ТКРС[[#This Row],[Скв]],'Каталог мероприятий'!A:A,'Каталог мероприятий'!Q:Q) -> КР-ОС-6
A15: центр | B15: 39 ГНКТ ООО "ИНК-ТКРС" | C15: Ki_4706 | D15: 47 | E15: 46082 | F15: 46092 | G15: 240 | H15: 250 | I15: 20 | J15: 166 | K15: КР13-2НТ | L15: НЗ - промывка после СТОП Ставить только КРС-39 нужна БДТ 50,8 (комбинированная), ТЗ по скважине 5800м. НЗ до МГРП-5 Н=4238м | M15: Пробурена | N15: 46089 | O15: 3 | P15: 46095 | S15: =_xlfn.XLOOKUP(Недельный_график_ТКРС[[#This Row],[Скв]],'Каталог мероприятий'!A:A,'Каталог мероприятий'!N:N,"нет карточки") -> ООО "ИНК-ТКРС" | T15: =_xlfn.XLOOKUP(Недельный_график_ТКРС[[#This Row],[Скв]],'Каталог мероприятий'!A:A,'Каталог мероприятий'!O:O,"нет карточки") -> 0 | U15: =_xlfn.XLOOKUP(Недельный_график_ТКРС[[#This Row],[Скв]],'Каталог мероприятий'!A:A,'Каталог мероприятий'!Q:Q) -> КР13-2НТ А
A16: центр | B16: 36 КРС ООО "ИНК-ТКРС" | C16: Msh_3703 | D16: 37 | E16: 46080 | F16: 46091 | G16: 264 | H16: 800 | I16: 0 | J16: 22 | K16: КР9-1 | L16: перевод в ППД | M16: - | S16: =_xlfn.XLOOKUP(Недельный_график_ТКРС[[#This Row],[Скв]],'Каталог мероприятий'!A:A,'Каталог мероприятий'!N:N,"нет карточки") -> ООО "ИНК-ТКРС" | T16: =_xlfn.XLOOKUP(Недельный_график_ТКРС[[#This Row],[Скв]],'Каталог мероприятий'!A:A,'Каталог мероприятий'!O:O,"нет карточки") -> 0 | U16: =_xlfn.XLOOKUP(Недельный_график_ТКРС[[#This Row],[Скв]],'Каталог мероприятий'!A:A,'Каталог мероприятий'!Q:Q) -> КР7-16
A17: центр | B17: 18 КРС ООО "ИНК-ТКРС" | C17: Au_369 | D17: 93 | E17: 46074 | F17: 46083 | G17: 216 | H17: 62 | I17: 2 | J17: 50 | K17: ТР5-1 | L17: Смена ЭЦН на отказной скважине | M17: - | S17: =_xlfn.XLOOKUP(Недельный_график_ТКРС[[#This Row],[Скв]],'Каталог мероприятий'!A:A,'Каталог мероприятий'!N:N,"нет карточки") -> нет карточки | T17: =_xlfn.XLOOKUP(Недельный_график_ТКРС[[#This Row],[Скв]],'Каталог мероприятий'!A:A,'Каталог мероприятий'!O:O,"нет карточки") -> нет карточки | U17: =_xlfn.XLOOKUP(Недельный_график_ТКРС[[#This Row],[Скв]],'Каталог мероприятий'!A:A,'Каталог мероприятий'!Q:Q) -> #N/A
A18: центр | B18: 18 КРС ООО "ИНК-ТКРС" | C18: Au_24403 | D18: 244 | E18: 46083 | F18: 46095 | G18: 288 | H18: 161 | I18: 62 | J18: 50 | K18: КР-ОС-4 | L18: ЗР ГРП, спуск ЭЦН, отработка ЭЦНом | M18: 04.12.2025 | O18: 1 | P18: 46064 | S18: =_xlfn.XLOOKUP(Недельный_график_ТКРС[[#This Row],[Скв]],'Каталог мероприятий'!A:A,'Каталог мероприятий'!N:N,"нет карточки") -> нет карточки | T18: =_xlfn.XLOOKUP(Недельный_график_ТКРС[[#This Row],[Скв]],'Каталог мероприятий'!A:A,'Каталог мероприятий'!O:O,"нет карточки") -> нет карточки | U18: =_xlfn.XLOOKUP(Недельный_график_ТКРС[[#This Row],[Скв]],'Каталог мероприятий'!A:A,'Каталог мероприятий'!Q:Q) -> #N/A
A19: центр | B19: 1 Андижон ООО "АндижонНГКТваБ"-Русь" | C19: Yaw_5604рс | D19: 56 | E19: 46082 | F19: 46091 | G19: 216 | H19: 0 | I19: 0 | J19: 0 | K19: ТР5-1 | L19: Смена ЭЦН на отказной скважине + ГИС (ИНГКС + СО + плотность и проводимость) 1560-2290м (спуск капилярной трубки) | M19: - | S19: =_xlfn.XLOOKUP(Недельный_график_ТКРС[[#This Row],[Скв]],'Каталог мероприятий'!A:A,'Каталог мероприятий'!N:N,"нет карточки") -> ООО "Андижон" | T19: =_xlfn.XLOOKUP(Недельный_график_ТКРС[[#This Row],[Скв]],'Каталог мероприятий'!A:A,'Каталог мероприятий'!O:O,"нет карточки") -> 0 | U19: =_xlfn.XLOOKUP(Недельный_график_ТКРС[[#This Row],[Скв]],'Каталог мероприятий'!A:A,'Каталог мероприятий'!Q:Q) -> ТР5-1
A20: центр | B20: 5 Андижон ООО "АндижонНГКТваБ"-Русь" | C20: Ya_242 | D20: 10 | E20: 46080 | F20: 46091 | G20: 264 | H20: 25 | I20: 6 | J20: 20 | K20: ТР5-1 | L20: Смена ЭЦН на отказной скважине + ПСШ, НЗ | M20: - | S20: =_xlfn.XLOOKUP(Недельный_график_ТКРС[[#This Row],[Скв]],'Каталог мероприятий'!A:A,'Каталог мероприятий'!N:N,"нет карточки") -> ООО "ИНК-ТКРС" | T20: =_xlfn.XLOOKUP(Недельный_график_ТКРС[[#This Row],[Скв]],'Каталог мероприятий'!A:A,'Каталог мероприятий'!O:O,"нет карточки") -> 0 | U20: =_xlfn.XLOOKUP(Недельный_график_ТКРС[[#This Row],[Скв]],'Каталог мероприятий'!A:A,'Каталог мероприятий'!Q:Q) -> ТР5-1
A21: центр | B21: 4 Андижон ООО "АндижонНГКТваБ"-Русь" | C21: Az_333 | D21: 82 | E21: 46083 | F21: 46092 | G21: 216 | H21: 76 | I21: 71 | J21: 18 | K21: ТР5-1 | L21: Смена ЭЦН на отказной скважине | M21: - | S21: =_xlfn.XLOOKUP(Недельный_график_ТКРС[[#This Row],[Скв]],'Каталог мероприятий'!A:A,'Каталог мероприятий'!N:N,"нет карточки") -> ООО "ИНК-ТКРС" | T21: =_xlfn.XLOOKUP(Недельный_график_ТКРС[[#This Row],[Скв]],'Каталог мероприятий'!A:A,'Каталог мероприятий'!O:O,"нет карточки") -> 28 | U21: =_xlfn.XLOOKUP(Недельный_график_ТКРС[[#This Row],[Скв]],'Каталог мероприятий'!A:A,'Каталог мероприятий'!Q:Q) -> ТР5-1
A22: центр | B22: 3 Андижон ООО "АндижонНГКТваБ"-Русь" | C22: Ya_212 | D22: 18 | E22: 46083 | F22: 46098 | G22: 360 | H22: 87 | I22: 50 | J22: 36 | K22: КР7-2 | L22: ПР к ГРП Vt; ГРП Vt; | M22: - | N22: 46102 | O22: 1 | P22: 46104 | S22: =_xlfn.XLOOKUP(Недельный_график_ТКРС[[#This Row],[Скв]],'Каталог мероприятий'!A:A,'Каталог мероприятий'!N:N,"нет карточки") -> нет карточки | T22: =_xlfn.XLOOKUP(Недельный_график_ТКРС[[#This Row],[Скв]],'Каталог мероприятий'!A:A,'Каталог мероприятий'!O:O,"нет карточки") -> нет карточки | U22: =_xlfn.XLOOKUP(Недельный_график_ТКРС[[#This Row],[Скв]],'Каталог мероприятий'!A:A,'Каталог мероприятий'!Q:Q) -> #N/A
S23: =_xlfn.XLOOKUP(Недельный_график_ТКРС[[#This Row],[Скв]],'Каталог мероприятий'!A:A,'Каталог мероприятий'!N:N,"нет карточки") -> #VALUE! | T23: =_xlfn.XLOOKUP(Недельный_график_ТКРС[[#This Row],[Скв]],'Каталог мероприятий'!A:A,'Каталог мероприятий'!O:O,"нет карточки") -> #VALUE! | U23: =_xlfn.XLOOKUP(Недельный_график_ТКРС[[#This Row],[Скв]],'Каталог мероприятий'!A:A,'Каталог мероприятий'!Q:Q) -> #VALUE!
S24: =_xlfn.XLOOKUP(Недельный_график_ТКРС[[#This Row],[Скв]],'Каталог мероприятий'!A:A,'Каталог мероприятий'!N:N,"нет карточки") -> #VALUE! | T24: =_xlfn.XLOOKUP(Недельный_график_ТКРС[[#This Row],[Скв]],'Каталог мероприятий'!A:A,'Каталог мероприятий'!O:O,"нет карточки") -> #VALUE! | U24: =_xlfn.XLOOKUP(Недельный_график_ТКРС[[#This Row],[Скв]],'Каталог мероприятий'!A:A,'Каталог мероприятий'!Q:Q) -> #VALUE!
S25: =_xlfn.XLOOKUP(Недельный_график_ТКРС[[#This Row],[Скв]],'Каталог мероприятий'!A:A,'Каталог мероприятий'!N:N,"нет карточки") -> #VALUE! | T25: =_xlfn.XLOOKUP(Недельный_график_ТКРС[[#This Row],[Скв]],'Каталог мероприятий'!A:A,'Каталог мероприятий'!O:O,"нет карточки") -> #VALUE! | U25: =_xlfn.XLOOKUP(Недельный_график_ТКРС[[#This Row],[Скв]],'Каталог мероприятий'!A:A,'Каталог мероприятий'!Q:Q) -> #VALUE!
S26: =_xlfn.XLOOKUP(Недельный_график_ТКРС[[#This Row],[Скв]],'Каталог мероприятий'!A:A,'Каталог мероприятий'!N:N,"нет карточки") -> #VALUE! | T26: =_xlfn.XLOOKUP(Недельный_график_ТКРС[[#This Row],[Скв]],'Каталог мероприятий'!A:A,'Каталог мероприятий'!O:O,"нет карточки") -> #VALUE! | U26: =_xlfn.XLOOKUP(Недельный_график_ТКРС[[#This Row],[Скв]],'Каталог мероприятий'!A:A,'Каталог мероприятий'!Q:Q) -> #VALUE!
S27: =_xlfn.XLOOKUP(Недельный_график_ТКРС[[#This Row],[Скв]],'Каталог мероприятий'!A:A,'Каталог мероприятий'!N:N,"нет карточки") -> #VALUE! | T27: =_xlfn.XLOOKUP(Недельный_график_ТКРС[[#This Row],[Скв]],'Каталог мероприятий'!A:A,'Каталог мероприятий'!O:O,"нет карточки") -> #VALUE! | U27: =_xlfn.XLOOKUP(Недельный_график_ТКРС[[#This Row],[Скв]],'Каталог мероприятий'!A:A,'Каталог мероприятий'!Q:Q) -> #VALUE!

Sheet Лист2

Sheet лист1

Sheet Каталог мероприятий
A1: Скважина | N1: Мероприятие | AS1: Результаты по дебиту | BD1: Дата (план)
N2: Исполнитель | W2: Дата (факт) | Z2: Продолжительность | AF2: Документы | AJ2: Статусы | AQ2: Затраты | AS2: Режим | AV2: На начало ремонта (зам.) | AZ2: Ожидаемые
A3: Инвентарный номер | B3: Номер | C3: Куст | D3: Месторождение | E3: НГДУ | F3: Участок недр | G3: Цех | H3: Состояние по фонду | I3: Способ эксплуатации до ремонта | J3: Площадь | K3: ЦИТС | L3: Недропользователь | N3: Подрядчик | O3: Бригада | P3: Тип мероприятия | Q3: Код мероприятия | R3: Примечания | S3: Способ эксплуатации после ремонта | T3: Сущ. категория | U3: Вид затрат | V3: Направление | W3: Начало мероприятия | X3: Конец мероприятия | Y3: Дата запуска по фонду | Z3: Календарное время по ремонту (ч) | AA3: Отработанное время по ремонту (ч) | AB3: Нормативное время по ремонту (ч) | AC3: Метео | AD3: Простои | AE3: Производительное время по ремонту (ч) | AF3: План работ/Наряд-заказ | AG3: Дизайн | AH3: Протокол | AI3: Акт | AJ3: Наряд-заказ | AK3: План работ | AL3: Дизайн | AM3: Протокол | AN3: Акт | AO3: Месяц подписания | AP3: Системный номер | AQ3: Ремонт (руб.) | AR3: Итого затрат (руб.) | AS3: Qн | AT3: Qж | AU3: %H2O | AV3: Qн | AW3: Qж | AX3: %H2O | AY3: Приемистость | AZ3: Qн | BA3: Qж | BB3: %H2O | BC3: Приемистость | BD3: Начало мероприятия | BE3: Конец мероприятия
A4: Ma_001г | B4: 001г | D4: Марковское | E4: Иркутская нефтяная компания | G4: ЦДНГ-1 | I4: ЭЦН | L4: ООО "ИНК" | N4: ООО "ИНК-ТКРС" | P4: КР | Q4: КР11-1 | R4: Консервация скважины | T4: вдз | W4: 0 | X4: 0 | Y4: 0 | Z4: 0 | AA4: 0 | AB4: 0 | AC4: 0 | AD4: 0 | AE4: 0 | AF4: True | AG4: False | AH4: False | AI4: False | AJ4: Макет | AK4: Макет | AN4: нет актов | AO4: декабрь | AQ4: 0 | AR4: 0 | AS4: 0 | AT4: 0 | AU4: 0 | AV4: 0 | AW4: 0 | AX4: 0 | AY4: 0 | AZ4: 0 | BA4: 0 | BB4: 0 | BC4: 0 | BD4: 46063 | BE4: 46068
A5: Ma_002укпг | B5: 002укпг | D5: Марковское | E5: Иркутская нефтяная компания | G5: ЦДНГ-1 | I5: ЭЦН | N5: ООО "ИНК-ТКРС" | P5: КР | Q5: КР13-13 | R5: Подъём ЭЦВ, Подъём ЭК, Проработка, Спуск ЭК, Спукс ЭЦВ | T5: вдз | W5: 0 | X5: 0 | Y5: 0 | Z5: 0 | AA5: 0 | AB5: 0 | AC5: 0 | AD5: 0 | AE5: 0 | AF5: True | AG5: False | AH5: False | AI5: False | AJ5: Макет | AK5: Макет | AN5: нет актов | AO5: декабрь | AQ5: 0 | AR5: 0 | AS5: 0 | AT5: 0 | AU5: 0 | AV5: 0 | AW5: 0 | AX5: 0 | AY5: 0 | AZ5: 0 | BA5: 0 | BB5: 0 | BC5: 0 | BD5: 46064 | BE5: 46074
A6: Mc_005A | B6: 005A | D6: Маччобинское | E6: Иркутская нефтяная компания | G6: ЦДНГ-1 | L6: ООО "Саханефть" | N6: ООО "ИНК-ТКРС" | O6: Звено подготовки скважин (МаччНГКМ) | P6: ТР | Q6: ТР00-6 | R6: Раскладка кабельной продукции на БУОС-2 | W6: 46064.333 | X6: 46064.833 | Y6: 0 | Z6: 12 | AA6: 0 | AB6: 0 | AC6: 0 | AD6: 0 | AE6: 0 | AF6: False | AG6: False | AH6: False | AI6: False | AN6: нет актов | AO6: декабрь | AQ6: 0 | AR6: 0 | AS6: 0 | AT6: 0 | AU6: 0 | AV6: 0 | AW6: 0 | AX6: 0 | AY6: 0 | AZ6: 0 | BA6: 0 | BB6: 0 | BC6: 0 | BD6: 46064 | BE6: 46064
A7: Mc_005A | B7: 005A | D7: Маччобинское | E7: Иркутская нефтяная компания | G7: ЦДНГ-1 | L7: ООО "Саханефть" | N7: ООО "ИНК-ТКРС" | O7: 27 | P7: ТР | Q7: ТР00-6 | R7: КП-4 МаччНГКМ укладка кабельной продукции | W7: 46064.448 | X7: 46064.958 | Y7: 0 | Z7: 12.25 | AA7: 11.23 | AB7: 11.23 | AC7: 0 | AD7: 0 | AE7: 11.23 | AF7: False | AG7: False | AH7: False | AI7: True | AN7: Закрыт | AO7: февраль | AQ7: 256662.32 | AR7: 256662.32 | AS7: 0 | AT7: 0 | AU7: 0 | AV7: 0 | AW7: 0 | AX7: 0 | AY7: 0 | AZ7: 0 | BA7: 0 | BB7: 0 | BC7: 0 | BD7: 46064 | BE7: 46064
A8: Mc_005A | B8: 005A | D8: Маччобинское | E8: Иркутская нефтяная компания | G8: ЦДНГ-1 | L8: ООО "Саханефть" | N8: ООО "ИНК-ТКРС" | O8: Звено подготовки скважин (МаччНГКМ) | P8: ТР | Q8: ТР00-9 | R8: Усиление КРС 37 на переезде на скв 20414 КП 8 МаччНГКМ | W8: 46066.375 | X8: 46067.833 | Y8: 0 | Z8: 35 | AA8: 0 | AB8: 0 | AC8: 0 | AD8: 0 | AE8: 0 | AF8: False | AG8: False | AH8: False | AI8: False | AN8: нет актов | AO8: декабрь | AQ8: 0 | AR8: 0 | AS8: 0 | AT8: 0 | AU8: 0 | AV8: 0 | AW8: 0 | AX8: 0 | AY8: 0 | AZ8: 0 | BA8: 0 | BB8: 0 | BC8: 0 | BD8: 46066 | BE8: 46068
A9: Mc_005A | B9: 005A | D9: Маччобинское | E9: Иркутская нефтяная компания | G9: ЦДНГ-1 | L9: ООО "Саханефть" | N9: ООО "ИНК-ТКРС" | O9: Звено подготовки скважин (МаччНГКМ) | P9: ТР | Q9: ТР00-5 | R9: сборка ВВЛ на скв 20402 | W9: 46069.375 | X9: 46069.833 | Y9: 0 | Z9: 11 | AA9: 0 | AB9: 0 | AC9: 0 | AD9: 0 | AE9: 0 | AF9: False | AG9: False | AH9: False | AI9: False | AN9: нет актов | AO9: декабрь | AQ9: 0 | AR9: 0 | AS9: 0 | AT9: 0 | AU9: 0 | AV9: 0 | AW9: 0 | AX9: 0 | AY9: 0 | AZ9: 0 | BA9: 0 | BB9: 0 | BC9: 0 | BD9: 46069 | BE9: 46070
A10: Mc_005A | B10: 005A | D10: Маччобинское | E10: Иркутская нефтяная компания | G10: ЦДНГ-1 | L10: ООО "Саханефть" | N10: ООО "ИНК-ТКРС" | O10: Звено подготовки скважин (МаччНГКМ) | P10: ТР | Q10: ТР00-6 | R10: Работа на БУОС1 по монтажу обратного клапана. | W10: 46066.042 | X10: 46066.375 | Y10: 0 | Z10: 8 | AA10: 0 | AB10: 0 | AC10: 0 | AD10: 0 | AE10: 0 | AF10: False | AG10: False | AH10: False | AI10: False | AN10: нет актов | AO10: декабрь | AQ10: 0 | AR10: 0 | AS10: 0 | AT10: 0 | AU10: 0 | AV10: 0 | AW10: 0 | AX10: 0 | AY10: 0 | AZ10: 0 | BA10: 0 | BB10: 0 | BC10: 0 | BD10: 46065 | BE10: 46067
A11: Mc_005A | B11: 005A | D11: Маччобинское | E11: Иркутская нефтяная компания | G11: ЦДНГ-1 | L11: ООО "Саханефть" | N11: ООО "ИНК-ТКРС" | O11: Звено подготовки скважин (МаччНГКМ) | P11: ТР | Q11: ТР00-6 | R11: Работа на БУОС-2, ОПЗ на КДМНУ-2 | W11: 46070.375 | X11: 0 | Y11: 0 | Z11: 0 | AA11: 0 | AB11: 0 | AC11: 0 | AD11: 0 | AE11: 0 | AF11: False | AG11: False | AH11: False | AI11: False | AN11: нет актов | AO11: декабрь | AQ11: 0 | AR11: 0 | AS11: 0 | AT11: 0 | AU11: 0 | AV11: 0 | AW11: 0 | AX11: 0 | AY11: 0 | AZ11: 0 | BA11: 0 | BB11: 0 | BC11: 0 | BD11: 46070 | BE11: 46071
A12: Mc_005A | B12: 005A | D12: Маччобинское | E12: Иркутская нефтяная компания | G12: ЦДНГ-1 | L12: ООО "Саханефть" | N12: ООО "ИНК-ТКРС" | O12: Звено подготовки скважин (МаччНГКМ) | P12: ТР | Q12: ТР00-6 | R12: Работы по погрузке и вывозу оборудования и хим. реагентов с КП 6 МаччНГКМ(после ремонта КРС 16). | W12: 46061.875 | X12: 46062.542 | Y12: 0 | Z12: 16 | AA12: 0 | AB12: 0 | AC12: 0 | AD12: 0 | AE12: 0 | AF12: False | AG12: False | AH12: False | AI12: False | AN12: нет актов | AO12: декабрь | AQ12: 0 | AR12: 0 | AS12: 0 | AT12: 0 | AU12: 0 | AV12: 0 | AW12: 0 | AX12: 0 | AY12: 0 | AZ12: 0 | BA12: 0 | BB12: 0 | BC12: 0 | BD12: 46061 | BE12: 46063
A13: Mc_005A | B13: 005A | D13: Маччобинское | E13: Иркутская нефтяная компания | G13: ЦДНГ-1 | L13: ООО "Саханефть" | N13: ООО "ИНК-ТКРС" | O13: 37 | P13: ТР | Q13: ТР00-6 | R13: Работы на БУОС-2 по монтажу печи. | W13: 46054.667 | X13: 46058.375 | Y13: 0 | Z13: 81 | AA13: 74.25 | AB13: 74 | AC13: 34 | AD13: 34 | AE13: 40.25 | AF13: False | AG13: False | AH13: False | AI13: True | AN13: Закрыт | AO13: февраль | AQ13: 1458152.8 | AR13: 1458152.8 | AS13: 0 | AT13: 0 | AU13: 0 | AV13: 0 | AW13: 0 | AX13: 0 | AY13: 0 | AZ13: 0 | BA13: 0 | BB13: 0 | BC13: 0 | BD13: 46054 | BE13: 46060
A14: Mc_005A | B14: 005A | D14: Маччобинское | E14: Иркутская нефтяная компания | G14: ЦДНГ-1 | L14: ООО "Саханефть" | N14: ООО "ИНК-ТКРС" | O14: Звено подготовки скважин (МаччНГКМ) | P14: ТР | Q14: ТР12-1 | R14: БУОС-1 МачНГКМ кислотная обработка. | W14: 46054.5 | X14: 46054.833 | Y14: 0 | Z14: 8 | AA14: 0 | AB14: 0 | AC14: 0 | AD14: 0 | AE14: 0 | AF14: False | AG14: False | AH14: False | AI14: False | AN14: нет актов | AO14: декабрь | AQ14: 0 | AR14: 0 | AS14: 0 | AT14: 0 | AU14: 0 | AV14: 0 | AW14: 0 | AX14: 0 | AY14: 0 | AZ14: 0 | BA14: 0 | BB14: 0 | BC14: 0 | BD14: 46054 | BE14: 46056
A15: Mc_005A | B15: 005A | D15: Маччобинское | E15: Иркутская нефтяная компания | G15: ЦДНГ-1 | L15: ООО "Саханефть" | N15: ООО "ИНК-ТКРС" | O15: Звено подготовки скважин (МаччНГКМ) | P15: ТР | Q15: ТР00-6 | R15: Работы на ЦДТ УВС по прокладке кабеля на КП19 МирнЛУ. | W15: 46055.333 | X15: 46059.208 | Y15: 0 | Z15: 93 | AA15: 0 | AB15: 0 | AC15: 25 | AD15: 25 | AE15: -25 | AF15: False | AG15: False | AH15: False | AI15: False | AN15: нет актов | AO15: декабрь | AQ15: 0 | AR15: 0 | AS15: 0 | AT15: 0 | AU15: 0 | AV15: 0 | AW15: 0 | AX15: 0 | AY15: 0 | AZ15: 0 | BA15: 0 | BB15: 0 | BC15: 0 | BD15: 46055 | BE15: 46059
A16: Mc_005A | B16: 005A | D16: Маччобинское | E16: Иркутская нефтяная компания | G16: ЦДНГ-1 | L16: ООО "Саханефть" | N16: ООО "ИНК-ТКРС" | O16: 27 | P16: ТР | Q16: ТР00-6 | R16: Размотку кабельной продукции для запуска скв.1515. Расчистка площадки обслуживания СУ от снега на КП-15, 17 МаччНГКМ | W16: 46063.458 | X16: 46063.833 | Y16: 0 | Z16: 9 | AA16: 8.25 | AB16: 8 | AC16: 0 | AD16: 0 | AE16: 8.25 | AF16: False | AG16: False | AH16: False | AI16: True | AN16: Закрыт | AO16: февраль | AQ16: 182840.48 | AR16: 182840.48 | AS16: 0 | AT16: 0 | AU16: 0 | AV16: 0 | AW16: 0 | AX16: 0 | AY16: 0 | AZ16: 0 | BA16: 0 | BB16: 0 | BC16: 0 | BD16: 46063 | BE16: 46063
A17: Mc_005A | B17: 005A | D17: Маччобинское | E17: Иркутская нефтяная компания | G17: ЦДНГ-1 | L17: ООО "Саханефть" | N17: ООО "ИНК-ТКРС" | O17: Звено подготовки скважин (МаччНГКМ) | P17: ТР | Q17: ТР00-9 | R17: Усиление КРС-16. Погрузка и разгрузка ОКРС. | W17: 46059.208 | X17: 46059.875 | Y17: 0 | Z17: 16 | AA17: 0 | AB17: 0 | AC17: 0 | AD17: 0 | AE17: 0 | AF17: False | AG17: False | AH17: False | AI17: False | AN17: нет актов | AO17: декабрь | AQ17: 0 | AR17: 0 | AS17: 0 | AT17: 0 | AU17: 0 | AV17: 0 | AW17: 0 | AX17: 0 | AY17: 0 | AZ17: 0 | BA17: 0 | BB17: 0 | BC17: 0 | BD17: 46059 | BE17: 46062
... A19: Mc_005A | B19: 005A | D19: Маччобинское | E19: Иркутская нефтяная компания | G19: ЦДНГ-1 | L19: ООО "Саханефть" | N19: ООО "ИНК-ТКРС" | O19: Звено подготовки скважин (МаччНГКМ) | P19: ТР | Q19: ТР00-3 | R19: Работа на КП-51 МаччНГКМ ЦДТ УВС по приготовлению раствора для гидроиспытаний. | W19: 46069.833 | X19: 46070.375 | Y19: 0 | Z19: 13 | AA19: 0 | AB19: 0 | AC19: 0 | AD19: 0 | AE19: 0 | AF19: False | AG19: False | AH19: False | AI19: False | AN19: нет актов | AO19: декабрь | AQ19: 0 | AR19: 0 | AS19: 0 | AT19: 0 | AU19: 0 | AV19: 0 | AW19: 0 | AX19: 0 | AY19: 0 | AZ19: 0 | BA19: 0 | BB19: 0 | BC19: 0 | BD19: 46069 | BE19: 46071
A20: Bt_20кпг | B20: 020кпг | C20: 20 | D20: Большетирский | E20: Иркутская нефтяная компания | F20: Большетирский лицензионный участок | G20: ЦДНГ-2 | H20: Освоение прошлых лет | I20: пр. | L20: АО «ИНК-Запад» | N20: ООО "ИНК-ТКРС" | O20: 1 | P20: ТР | Q20: ТР8-1 | R20: Подъём воронки, ОТЗ, НЗ, Спуск ЭЦН | T20: вдз | W20: 0 | X20: 0 | Y20: 0 | Z20: 0 | AA20: 0 | AB20: 0 | AC20: 0 | AD20: 0 | AE20: 0 | AF20: True | AG20: False | AH20: False | AI20: False | AK20: Утвержден | AN20: нет актов | AO20: декабрь | AQ20: 0 | AR20: 0 | AS20: 0 | AT20: 462 | AU20: 0 | AV20: 0 | AW20: 462 | AX20: 0 | AY20: 0 | AZ20: 0 | BA20: 462 | BB20: 0 | BC20: 0 | BD20: 46058 | BE20: 46068
A21: Ma_025р | B21: 025Р | D21: Марковское | E21: Иркутская нефтяная компания | G21: ЦДНГ-1 | N21: ООО "ИНК-ТКРС" | O21: Звено освоения №3 | P21: КР | Q21: КР12-2 | R21: Восстановление устья. Шаблонировка ОК-146 с разбуриванием ЦМ. ГИС. ПВР. Спуск пакера ГРП. Отработка скважины после ГРП (при необходимости НЗ). Ликвидация/консервация скважины (по доп. НЗ и ПР). | W21: 0 | X21: 0 | Y21: 0 | Z21: 0 | AA21: 0 | AB21: 0 | AC21: 0 | AD21: 0 | AE21: 0 | AF21: False | AG21: False | AH21: False | AI21: False | AN21: нет актов | AO21: декабрь | AQ21: 0 | AR21: 0 | AS21: 0 | AT21: 0 | AU21: 0 | AV21: 0 | AW21: 0 | AX21: 0 | AY21: 0 | AZ21: 0 | BA21: 0 | BB21: 0 | BC21: 0 | BD21: 46042 | BE21: 46073
A22: Ma_040г | B22: 040г | D22: Марковское | E22: Иркутская нефтяная компания | G22: ЦДНГ-1 | I22: ЭЦН | L22: ООО "ИНК" | N22: ООО "ИНК-ТКРС" | P22: КР | Q22: КР11-1 | R22: Консервация скважины | T22: вдз | W22: 0 | X22: 0 | Y22: 0 | Z22: 0 | AA22: 0 | AB22: 0 | AC22: 0 | AD22: 0 | AE22: 0 | AF22: True | AG22: False | AH22: False | AI22: False | AJ22: Макет | AK22: Макет | AN22: нет актов | AO22: декабрь | AQ22: 0 | AR22: 0 | AS22: 0 | AT22: 0 | AU22: 0 | AV22: 0 | AW22: 0 | AX22: 0 | AY22: 0 | AZ22: 0 | BA22: 0 | BB22: 0 | BC22: 0 | BD22: 46068 | BE22: 46071
A23: Ki_047г | B23: 047г | D23: Кийский | E23: Иркутская нефтяная компания | G23: ЦДНГ-1 | I23: ЭЦН | L23: ООО "ИНК" | N23: ООО "ИНК-ТКРС" | O23: 24 | P23: КР | Q23: КР13-13 | R23: Подъём ЭЦВ, Извлечение аварийного оборуд, Подъём ЭК, Добуривание до 250м, Спуск ЭК, | T23: вдз | W23: 0 | X23: 0 | Y23: 0 | Z23: 0 | AA23: 0 | AB23: 0 | AC23: 0 | AD23: 0 | AE23: 0 | AF23: True | AG23: False | AH23: False | AI23: False | AJ23: Утвержден | AK23: Готов | AN23: нет актов | AO23: декабрь | AQ23: 0 | AR23: 0 | AS23: 0 | AT23: 0 | AU23: 0 | AV23: 0 | AW23: 0 | AX23: 0 | AY23: 0 | AZ23: 0 | BA23: 0 | BB23: 0 | BC23: 0 | BD23: 46069 | BE23: 46073
A24: Vt_081вз | B24: 081вз | C24: 81 | D24: Верхнетирский | E24: Иркутская нефтяная компания | F24: Участок Большетирского месторождения Vt LU | G24: ЦДНГ-2 | H24: Ожидание освоения прошлых лет | I24: пр. | L24: ООО «ИНК» | N24: ООО "ИНК-ТКРС" | O24: Звено глушения №2 | P24: ТР | Q24: ТР12-1 | R24: Работы на КДМНУ-81-3 Монтаж УЭЦН | S24: пр. | T24: вдз | W24: 46057.375 | X24: 46063.833 | Y24: 0 | Z24: 66 | AA24: 0 | AB24: 0 | AC24: 0 | AD24: 0 | AE24: 0 | AF24: True | AG24: False | AH24: False | AI24: False | AK24: Утвержден | AN24: нет актов | AO24: декабрь | AQ24: 0 | AR24: 0 | AS24: 0 | AT24: 0 | AU24: 0 | AV24: 0 | AW24: 0 | AX24: 0 | AY24: 0 | AZ24: 0 | BA24: 0 | BB24: 0 | BC24: 0 | BD24: 46053 | BE24: 46056
A25: Vt_089г | B25: 089г | D25: Верхнетирский | E25: Иркутская нефтяная компания | G25: ЦДНГ-2 | I25: ЭЦН | L25: ООО "ИНК" | N25: ООО "ИНК-ТКРС" | P25: ТР | Q25: ТР8-1 | R25: спуск ЭЦН | T25: вдз | W25: 0 | X25: 0 | Y25: 0 | Z25: 0 | AA25: 0 | AB25: 0 | AC25: 0 | AD25: 0 | AE25: 0 | AF25: True | AG25: False | AH25: False | AI25: False | AK25: Готов | AN25: нет актов | AO25: декабрь | AQ25: 0 | AR25: 0 | AS25: 0 | AT25: 0 | AU25: 0 | AV25: 0 | AW25: 0 | AX25: 0 | AY25: 0 | AZ25: 0 | BA25: 0 | BB25: 0 | BC25: 0 | BD25: 46072 | BE25: 46073
A26: Vt_089г | B26: 089г | D26: Верхнетирский | E26: Иркутская нефтяная компания | G26: ЦДНГ-2 | I26: ЭЦН | L26: ООО "ИНК" | N26: ООО "ИНК-ТКРС" | O26: 34 | P26: ТР | Q26: ТР00-6 | R26: ОТЗ, НЗ, Шаблонировка, Замер приемистости, ОПЗ по результату, Спуск ЭЦН | S26: ЭЦН | T26: вдз | W26: 46050.542 | X26: 46069.375 | Y26: 0 | Z26: 67 | AA26: 61.42 | AB26: 47.28 | AC26: 19 | AD26: 19 | AE26: 42.42 | AF26: True | AG26: False | AH26: False | AI26: True | AK26: Утвержден | AN26: несколько актов | AO26: февраль | AQ26: 960952.27 | AR26: 960952.27 | AS26: 0 | AT26: 0 | AU26: 0 | AV26: 0 | AW26: 0 | AX26: 0 | AY26: 0 | AZ26: 0 | BA26: 308 | BB26: 0 | BC26: 0 | BD26: 46028 | BE26: 46032
A27: Mc_010 | B27: 10 | C27: 10 | D27: Маччобинское | E27: Иркутская нефтяная компания | F27: Мирнинский ЛУ | G27: УДНГ | H27: В работе | I27: ЭЦН | L27: ООО "Саханефть" | N27: ООО "ИНК-ТКРС" | O27: Звено подготовки скважин (МаччНГКМ) | P27: ТР | Q27: ТР.ПНП1-4 | R27: проведение двухэтапной обработки | S27: ЭЦН | T27: неф | W27: 46061.375 | X27: 46061.875 | Z27: 12 | AA27: 0 | AB27: 0 | AC27: 0 | AD27: 0 | AE27: 0 | AF27: False | AG27: False | AH27: False | AI27: False | AN27: нет актов | AO27: декабрь | AQ27: 0 | AR27: 0 | AS27: 105.83 | AT27: 730 | AU27: 83 | AV27: 105.83 | AW27: 730 | AX27: 83 | AY27: 0 | AZ27: 105.83 | BA27: 730 | BB27: 83 | BC27: 0 | BD27: 46061 | BE27: 46062
A28: Mc_010 | B28: 10 | C28: 10 | D28: Маччобинское | E28: Иркутская нефтяная компания | F28: Мирнинский ЛУ | G28: УДНГ | I28: ЭЦН | L28: ООО "Саханефть" | N28: ООО "ИНК-ТКРС" | O28: Звено подготовки скважин (МаччНГКМ) | P28: ТР | Q28: ТР.ПНП1-4 | R28: Проведение 2-х этапного ОПЗ | S28: ЭЦН | T28: неф | W28: 46059.875 | X28: 46060.542 | Z28: 16 | AA28: 0 | AB28: 0 | AC28: 0 | AD28: 0 | AE28: 0 | AF28: False | AG28: False | AH28: False | AI28: False | AN28: нет актов | AO28: декабрь | AQ28: 0 | AR28: 0 | AS28: 143.1818 | AT28: 730 | AU28: 77 | AV28: 143.1818 | AW28: 730 | AX28: 77 | AY28: 0 | AZ28: 143.1818 | BA28: 730 | BB28: 77 | BC28: 0 | BD28: 46059 | BE28: 46061
A29: Mc_1001 | B29: 1001 | C29: 10 | D29: Маччобинское | E29: Иркутская нефтяная компания | F29: Мирнинский ЛУ | G29: УДНГ | I29: ЭЦН | L29: ООО "Саханефть" | N29: ООО "ИНК-ТКРС" | O29: 37 | P29: ТР | Q29: ТР3-2 | R29: Глушение, смена УЭЦН (оптимизация) | S29: ЭЦН | T29: неф | W29: 46053.833 | X29: 46062.819 | Y29: 45573 | Z29: 126.67 | AA29: 116.11 | AB29: 134.47 | AC29: 0 | AD29: 0 | AE29: 116.11 | AF29: True | AG29: False | AH29: False | AI29: True | AK29: Утвержден | AN29: несколько актов | AO29: февраль | AQ29: 3064337.9 | AR29: 3064337.9 | AS29: 138.8472 | AT29: 161 | AU29: 0.3 | AV29: 138.8472 | AW29: 161 | AX29: 0.3 | AY29: 0 | AZ29: 221 | BA29: 255 | BB29: 0.3 | BC29: 0 | BD29: 46053 | BE29: 46062
A30: Mc_1004 | B30: 1004 | C30: 10 | D30: Маччобинское | E30: Иркутская нефтяная компания | F30: Мирнинский ЛУ | G30: УДНГ | H30: В работе | I30: ЭЦН | L30: ООО "Саханефть" | N30: ООО "ИНК-ТКРС" | O30: 7 | P30: КР | Q30: КР13-1.3НТ | R30: ВЦ | S30: ЭЦН | T30: неф | W30: 46062.208 | X30: 46070.375 | Y30: 45678 | Z30: 196 | AA30: 179.67 | AB30: 141 | AC30: 0 | AD30: 5.5 | AE30: 174.17 | AF30: True | AG30: False | AH30: False | AI30: True | AJ30: Утвержден | AK30: Утвержден | AN30: Макет | AO30: февраль | AQ30: 4454857.1 | AR30: 4454857.1 | AS30: 65.7 | AT30: 165 | AU30: 54 | AV30: 65.6535 | AW30: 165 | AX30: 54 | AY30: 0 | AZ30: 138 | BA30: 165 | BB30: 20 | BC30: 0 | BD30: 46065 | BE30: 46072
A31: Mc_1004 | B31: 1004 | C31: 10 | D31: Маччобинское | E31: Иркутская нефтяная компания | F31: Мирнинский ЛУ | G31: УДНГ | H31: В работе | I31: ЭЦН | L31: ООО "Саханефть" | N31: ООО "ИНК-ТКРС" | O31: Звено подготовки скважин (МаччНГКМ) | P31: ТР | Q31: ТР.ПНП1-4 | R31: ОПЗ на Скв 1004. КП10 МаччНГКМ | T31: неф | W31: 46054.833 | X31: 46055.333 | Y31: 0 | Z31: 12 | AA31: 0 | AB31: 0 | AC31: 0 | AD31: 0 | AE31: 0 | AF31: False | AG31: False | AH31: False | AI31: False | AN31: нет актов | AO31: декабрь | AQ31: 0 | AR31: 0 | AS31: 138.4433 | AT31: 165 | AU31: 3 | AV31: 138.4433 | AW31: 165 | AX31: 3 | AY31: 0 | AZ31: 138.4433 | BA31: 165 | BB31: 3 | BC31: 0 | BD31: 46054 | BE31: 46055
A32: Mc_1004 | B32: 1004 | C32: 10 | D32: Маччобинское | E32: Иркутская нефтяная компания | F32: Мирнинский ЛУ | G32: УДНГ | I32: ЭЦН | L32: ООО "Саханефть" | N32: ООО "ИНК-ТКРС" | O32: Звено подготовки скважин (МаччНГКМ) | P32: ТР | Q32: ТР12-1 | R32: Проведение ОПЗ, ГКР 12% | S32: ЭЦН | T32: неф | W32: 46060.875 | X32: 46061.375 | Y32: 0 | Z32: 12 | AA32: 0 | AB32: 0 | AC32: 0 | AD32: 0 | AE32: 0 | AF32: False | AG32: False | AH32: False | AI32: False | AN32: нет актов | AO32: декабрь | AQ32: 0 | AR32: 0 | AS32: 65.6535 | AT32: 165 | AU32: 54 | AV32: 65.6535 | AW32: 165 | AX32: 54 | AY32: 0 | AZ32: 65.6535 | BA32: 165 | BB32: 54 | BC32: 0 | BD32: 46060 | BE32: 46062
A33: Ya_104 | B33: 104 | C33: 3 | D33: Ярактинское | E33: Иркутская нефтяная компания | F33: Ярактинское месторождение | G33: ЦДНГ-1 | H33: В работе | I33: ЭЦН | L33: ООО «ИНК» | N33: ООО "Андижон" | O33: 4 | P33: ТР | Q33: ТР5-1 | R33: Смена УЭЦН | T33: неф | W33: 0 | X33: 0 | Y33: 0 | Z33: 0 | AA33: 0 | AB33: 0 | AC33: 0 | AD33: 0 | AE33: 0 | AF33: True | AG33: False | AH33: True | AI33: False | AK33: Макет | AM33: Макет | AN33: нет актов | AO33: декабрь | AQ33: 0 | AR33: 0 | AS33: 11.7635 | AT33: 473 | AU33: 97 | AV33: 11.7635 | AW33: 473 | AX33: 97 | AY33: 0 | AZ33: 11.7635 | BA33: 473 | BB33: 97 | BC33: 0 | BD33: 46070 | BE33: 46078
A34: Au_10501г | B34: 10501г | D34: Аянский участок | E34: Иркутская нефтяная компания | G34: ЦДНГ-1 | I34: ЭЦН | L34: ООО "ИНК-НефтеГазГеология" | N34: ООО "Андижон" | O34: 6 | P34: ТР | Q34: ТР8-1 | R34: Смена ЭЦВ | S34: ЭЦН | T34: вдз | W34: 46058.75 | X34: 46059.792 | Y34: 45742 | Z34: 25 | AA34: 23.33 | AB34: 23.21 | AC34: 0 | AD34: 0 | AE34: 23.33 | AF34: True | AG34: False | AH34: False | AI34: True | AK34: Готов | AN34: Макет | AO34: февраль | AQ34: 675117.83 | AR34: 675117.83 | AS34: 0 | AT34: 120 | AU34: 100 | AV34: 0 | AW34: 120 | AX34: 100 | AY34: 0 | AZ34: 0 | BA34: 120 | BB34: 100 | BC34: 0 | BD34: 46056 | BE34: 46063
A35: Vt_1051вз | B35: 1051вз | D35: Верхнетирский | E35: Иркутская нефтяная компания | G35: ЦДНГ-2 | I35: ЭЦН | L35: ООО "ИНК" | N35: ООО "ИНК-ТКРС" | O35: 5 | P35: ТР | Q35: ТР8-1 | R35: КЗИ, смена ЭЦН | S35: ЭЦН | T35: вдз | W35: 46063.75 | X35: 46066.125 | Y35: 46052 | Z35: 57 | AA35: 52.25 | AB35: 68.45 | AC35: 0 | AD35: 0 | AE35: 52.25 | AF35: True | AG35: False | AH35: True | AI35: True | AK35: Утвержден | AM35: Макет | AN35: Макет | AO35: февраль | AQ35: 1345608.8 | AR35: 1345608.8 | AS35: 0 | AT35: 0 | AU35: 0 | AV35: 0 | AW35: 0 | AX35: 0 | AY35: 0 | AZ35: 0 | BA35: 0 | BB35: 0 | BC35: 0 | BD35: 46063 | BE35: 46065
A36: Vt_1051вз | B36: 1051вз | D36: Верхнетирский | E36: Иркутская нефтяная компания | G36: ЦДНГ-2 | I36: ЭЦН | L36: ООО "ИНК" | N36: ООО "ИНК-ТКРС" | O36: 34 | P36: ТР | Q36: ТР8-1 | R36: Ревизия КВВД, по рез-ту смена УЭЦН | S36: ЭЦН | T36: вдз | W36: 46051.5 | X36: 46054.708 | Y36: 46052 | Z36: 77 | AA36: 70.58 | AB36: 45.33 | AC36: 23.75 | AD36: 32.92 | AE36: 37.66 | AF36: True | AG36: False | AH36: False | AI36: True | AK36: Утвержден | AN36: несколько актов | AO36: февраль | AQ36: 986075.88 | AR36: 986075.88 | AS36: 0 | AT36: 0 | AU36: 0 | AV36: 0 | AW36: 0 | AX36: 0 | AY36: 0 | AZ36: 0 | BA36: 0 | BB36: 0 | BC36: 0 | BD36: 46051 | BE36: 46052
A37: Ya_118 | B37: 118 | C37: 18 | D37: Ярактинское | E37: Иркутская нефтяная компания | F37: Ярактинское месторождение | G37: ЦДНГ-1 | I37: ЭЦН | L37: ООО «ИНК» | N37: ООО "Андижон" | O37: 4 | P37: ТР | Q37: ТР13-2 | R37: Смена ЗМС №2 и №4 | S37: ЭЦН | T37: неф | W37: 46067.958 | X37: 46070.208 | Y37: 43921 | Z37: 54 | AA37: 50.4 | AB37: 23.26 | AC37: 0 | AD37: 0 | AE37: 50.4 | AF37: True | AG37: False | AH37: False | AI37: True | AK37: Утвержден | AN37: Макет | AO37: февраль | AQ37: 672174.13 | AR37: 672174.13 | AS37: 19.6888 | AT37: 25 | AU37: 5 | AV37: 19.6888 | AW37: 25 | AX37: 5 | AY37: 0 | AZ37: 19.6888 | BA37: 25 | BB37: 5 | BC37: 0 | BD37: 46066 | BE37: 46077
A38: Bt_1203 | B38: 1203 | C38: 12 | D38: Большетирский | E38: Иркутская нефтяная компания | F38: Большетирский лицензионный участок | G38: ЦДНГ-2 | I38: ФОН | L38: АО «ИНК-Запад» | N38: ООО "ИНК-ТКРС" | P38: КР | Q38: КР-ОС-6 | R38: Отработка скважины. Замер дебита. ГДИ. | T38: неф | W38: 0 | X38: 0 | Y38: 0 | Z38: 0 | AA38: 0 | AB38: 0 | AC38: 0 | AD38: 0 | AE38: 0 | AF38: True | AG38: False | AH38: False | AI38: False | AJ38: Утвержден | AK38: Утвержден | AN38: нет актов | AO38: декабрь | AQ38: 0 | AR38: 0 | AS38: 0 | AT38: 0 | AU38: 0 | AV38: 0 | AW38: 0 | AX38: 0 | AY38: 0 | AZ38: 200.7 | BA38: 251 | BB38: 1 | BC38: 0 | BD38: 46047 | BE38: 46055
A39: Ya_122 | B39: 122 | C39: 3 | D39: Ярактинское | E39: Иркутская нефтяная компания | F39: Ярактинское месторождение | G39: ЦДНГ-1 | H39: Остановлена | I39: ЭЦН | L39: ООО «ИНК» | N39: ООО "Андижон" | O39: 3 | P39: КР | Q39: КР7-2 | R39: Подъем ЭЦН, ОТЗ,НЗ, ПВР ,спуск пакера ГРП. | S39: ЭЦН | T39: неф | W39: 46066.875 | X39: 0 | Y39: 43717 | Z39: 0 | AA39: 0 | AB39: 120.6 | AC39: 0 | AD39: 0 | AE39: 0 | AF39: True | AG39: False | AH39: False | AI39: True | AJ39: Утвержден | AK39: Утвержден | AN39: Макет | AO39: февраль | AQ39: 3503052.1 | AR39: 3503052.1 | AS39: 22.7063 | AT39: 330 | AU39: 91.7 | AV39: 22.3623 | AW39: 325 | AX39: 91.7 | AY39: 0 | AZ39: 50.4 | BA39: 810.4 | BB39: 92.5 | BC39: 0 | BD39: 46074 | BE39: 46087
A40: Ya_125 | B40: 125 | C40: 9 | D40: Ярактинское | E40: Иркутская нефтяная компания | F40: Ярактинское месторождение | G40: ЦДНГ-1 | H40: Остановлена | I40: ЭЦН | L40: ООО «ИНК» | N40: ООО "ИНК-ТКРС" | P40: ТР | Q40: ТР5-1 | R40: Смена УЭЦН | T40: неф | W40: 0 | X40: 0 | Y40: 0 | Z40: 0 | AA40: 0 | AB40: 0 | AC40: 0 | AD40: 0 | AE40: 0 | AF40: True | AG40: False | AH40: True | AI40: False | AK40: Макет | AM40: Макет | AN40: нет актов | AO40: декабрь | AQ40: 0 | AR40: 0 | AS40: 3.515 | AT40: 106 | AU40: 96 | AV40: 3.515 | AW40: 106 | AX40: 96 | AY40: 0 | AZ40: 3.515 | BA40: 106 | BB40: 96 | BC40: 0 | BD40: 46050 | BE40: 46078
A41: Ma_012г | B41: 12г | D41: Марковское | E41: Иркутская нефтяная компания | G41: ЦДНГ-1 | I41: ЭЦН | L41: ООО "ИНК" | N41: ООО "ИНК-ТКРС" | P41: КР | Q41: КР11-1 | R41: Консервация скв | T41: вдз | W41: 0 | X41: 0 | Y41: 0 | Z41: 0 | AA41: 0 | AB41: 0 | AC41: 0 | AD41: 0 | AE41: 0 | AF41: True | AG41: False | AH41: False | AI41: False | AJ41: Макет | AK41: Макет | AN41: нет актов | AO41: декабрь | AQ41: 0 | AR41: 0 | AS41: 0 | AT41: 0 | AU41: 0 | AV41: 0 | AW41: 0 | AX41: 0 | AY41: 0 | AZ41: 0 | BA41: 0 | BB41: 0 | BC41: 0 | BD41: 46067 | BE41: 46069
...
